[2023-12-06T00:14:41.731+0000] {taskinstance.py:1159} INFO - Dependencies all met for dep_context=non-requeueable deps ti=<TaskInstance: dag_spotify.limpio_data_frame scheduled__2023-12-05T23:00:00+00:00 [queued]>
[2023-12-06T00:14:41.737+0000] {taskinstance.py:1159} INFO - Dependencies all met for dep_context=requeueable deps ti=<TaskInstance: dag_spotify.limpio_data_frame scheduled__2023-12-05T23:00:00+00:00 [queued]>
[2023-12-06T00:14:41.737+0000] {taskinstance.py:1361} INFO - Starting attempt 3 of 4
[2023-12-06T00:14:41.743+0000] {taskinstance.py:1382} INFO - Executing <Task(PythonOperator): limpio_data_frame> on 2023-12-05 23:00:00+00:00
[2023-12-06T00:14:41.746+0000] {standard_task_runner.py:57} INFO - Started process 397 to run task
[2023-12-06T00:14:41.748+0000] {standard_task_runner.py:84} INFO - Running: ['***', 'tasks', 'run', 'dag_spotify', 'limpio_data_frame', 'scheduled__2023-12-05T23:00:00+00:00', '--job-id', '11', '--raw', '--subdir', 'DAGS_FOLDER/dag_spotify.py', '--cfg-path', '/tmp/tmp1uuw3oii']
[2023-12-06T00:14:41.749+0000] {standard_task_runner.py:85} INFO - Job 11: Subtask limpio_data_frame
[2023-12-06T00:14:41.784+0000] {task_command.py:416} INFO - Running <TaskInstance: dag_spotify.limpio_data_frame scheduled__2023-12-05T23:00:00+00:00 [running]> on host a0b7865f4cae
[2023-12-06T00:14:41.831+0000] {taskinstance.py:1662} INFO - Exporting env vars: AIRFLOW_CTX_DAG_OWNER='***' AIRFLOW_CTX_DAG_ID='dag_spotify' AIRFLOW_CTX_TASK_ID='limpio_data_frame' AIRFLOW_CTX_EXECUTION_DATE='2023-12-05T23:00:00+00:00' AIRFLOW_CTX_TRY_NUMBER='3' AIRFLOW_CTX_DAG_RUN_ID='scheduled__2023-12-05T23:00:00+00:00'
[2023-12-06T00:14:41.832+0000] {taskinstance.py:1937} ERROR - Task failed with exception
Traceback (most recent call last):
  File "/home/airflow/.local/lib/python3.8/site-packages/airflow/operators/python.py", line 192, in execute
    return_value = self.execute_callable()
  File "/home/airflow/.local/lib/python3.8/site-packages/airflow/operators/python.py", line 209, in execute_callable
    return self.python_callable(*self.op_args, **self.op_kwargs)
TypeError: limpio_data_frame() missing 1 required positional argument: 'new'
[2023-12-06T00:14:41.839+0000] {taskinstance.py:1400} INFO - Marking task as UP_FOR_RETRY. dag_id=dag_spotify, task_id=limpio_data_frame, execution_date=20231205T230000, start_date=20231206T001441, end_date=20231206T001441
[2023-12-06T00:14:41.846+0000] {standard_task_runner.py:104} ERROR - Failed to execute job 11 for task limpio_data_frame (limpio_data_frame() missing 1 required positional argument: 'new'; 397)
[2023-12-06T00:14:41.881+0000] {local_task_job_runner.py:228} INFO - Task exited with return code 1
[2023-12-06T00:14:41.893+0000] {taskinstance.py:2778} INFO - 0 downstream tasks scheduled from follow-on schedule check
