[2023-12-06T00:12:39.856+0000] {taskinstance.py:1159} INFO - Dependencies all met for dep_context=non-requeueable deps ti=<TaskInstance: dag_spotify.limpio_data_frame scheduled__2023-12-05T23:00:00+00:00 [queued]>
[2023-12-06T00:12:39.861+0000] {taskinstance.py:1159} INFO - Dependencies all met for dep_context=requeueable deps ti=<TaskInstance: dag_spotify.limpio_data_frame scheduled__2023-12-05T23:00:00+00:00 [queued]>
[2023-12-06T00:12:39.861+0000] {taskinstance.py:1361} INFO - Starting attempt 1 of 4
[2023-12-06T00:12:39.866+0000] {taskinstance.py:1382} INFO - Executing <Task(PythonOperator): limpio_data_frame> on 2023-12-05 23:00:00+00:00
[2023-12-06T00:12:39.868+0000] {standard_task_runner.py:57} INFO - Started process 311 to run task
[2023-12-06T00:12:39.870+0000] {standard_task_runner.py:84} INFO - Running: ['***', 'tasks', 'run', 'dag_spotify', 'limpio_data_frame', 'scheduled__2023-12-05T23:00:00+00:00', '--job-id', '7', '--raw', '--subdir', 'DAGS_FOLDER/dag_spotify.py', '--cfg-path', '/tmp/tmpa09p4cb7']
[2023-12-06T00:12:39.872+0000] {standard_task_runner.py:85} INFO - Job 7: Subtask limpio_data_frame
[2023-12-06T00:12:39.898+0000] {task_command.py:416} INFO - Running <TaskInstance: dag_spotify.limpio_data_frame scheduled__2023-12-05T23:00:00+00:00 [running]> on host a0b7865f4cae
[2023-12-06T00:12:39.935+0000] {taskinstance.py:1662} INFO - Exporting env vars: AIRFLOW_CTX_DAG_OWNER='***' AIRFLOW_CTX_DAG_ID='dag_spotify' AIRFLOW_CTX_TASK_ID='limpio_data_frame' AIRFLOW_CTX_EXECUTION_DATE='2023-12-05T23:00:00+00:00' AIRFLOW_CTX_TRY_NUMBER='1' AIRFLOW_CTX_DAG_RUN_ID='scheduled__2023-12-05T23:00:00+00:00'
[2023-12-06T00:12:39.936+0000] {taskinstance.py:1937} ERROR - Task failed with exception
Traceback (most recent call last):
  File "/home/airflow/.local/lib/python3.8/site-packages/airflow/operators/python.py", line 192, in execute
    return_value = self.execute_callable()
  File "/home/airflow/.local/lib/python3.8/site-packages/airflow/operators/python.py", line 209, in execute_callable
    return self.python_callable(*self.op_args, **self.op_kwargs)
TypeError: limpio_data_frame() missing 1 required positional argument: 'new'
[2023-12-06T00:12:39.942+0000] {taskinstance.py:1400} INFO - Marking task as UP_FOR_RETRY. dag_id=dag_spotify, task_id=limpio_data_frame, execution_date=20231205T230000, start_date=20231206T001239, end_date=20231206T001239
[2023-12-06T00:12:39.947+0000] {standard_task_runner.py:104} ERROR - Failed to execute job 7 for task limpio_data_frame (limpio_data_frame() missing 1 required positional argument: 'new'; 311)
[2023-12-06T00:12:39.963+0000] {local_task_job_runner.py:228} INFO - Task exited with return code 1
[2023-12-06T00:12:39.976+0000] {taskinstance.py:2778} INFO - 0 downstream tasks scheduled from follow-on schedule check
[2023-12-06T00:19:03.525+0000] {taskinstance.py:1159} INFO - Dependencies all met for dep_context=non-requeueable deps ti=<TaskInstance: dag_spotify.limpio_data_frame scheduled__2023-12-05T23:00:00+00:00 [queued]>
[2023-12-06T00:19:03.529+0000] {taskinstance.py:1159} INFO - Dependencies all met for dep_context=requeueable deps ti=<TaskInstance: dag_spotify.limpio_data_frame scheduled__2023-12-05T23:00:00+00:00 [queued]>
[2023-12-06T00:19:03.529+0000] {taskinstance.py:1361} INFO - Starting attempt 1 of 4
[2023-12-06T00:19:03.535+0000] {taskinstance.py:1382} INFO - Executing <Task(PythonOperator): limpio_data_frame> on 2023-12-05 23:00:00+00:00
[2023-12-06T00:19:03.538+0000] {standard_task_runner.py:57} INFO - Started process 210 to run task
[2023-12-06T00:19:03.540+0000] {standard_task_runner.py:84} INFO - Running: ['***', 'tasks', 'run', 'dag_spotify', 'limpio_data_frame', 'scheduled__2023-12-05T23:00:00+00:00', '--job-id', '20', '--raw', '--subdir', 'DAGS_FOLDER/dag_spotify.py', '--cfg-path', '/tmp/tmp9pdltkaa']
[2023-12-06T00:19:03.542+0000] {standard_task_runner.py:85} INFO - Job 20: Subtask limpio_data_frame
[2023-12-06T00:19:03.570+0000] {task_command.py:416} INFO - Running <TaskInstance: dag_spotify.limpio_data_frame scheduled__2023-12-05T23:00:00+00:00 [running]> on host 1b18a67fdeec
[2023-12-06T00:19:03.610+0000] {taskinstance.py:1662} INFO - Exporting env vars: AIRFLOW_CTX_DAG_OWNER='***' AIRFLOW_CTX_DAG_ID='dag_spotify' AIRFLOW_CTX_TASK_ID='limpio_data_frame' AIRFLOW_CTX_EXECUTION_DATE='2023-12-05T23:00:00+00:00' AIRFLOW_CTX_TRY_NUMBER='1' AIRFLOW_CTX_DAG_RUN_ID='scheduled__2023-12-05T23:00:00+00:00'
[2023-12-06T00:19:03.611+0000] {taskinstance.py:1937} ERROR - Task failed with exception
Traceback (most recent call last):
  File "/home/airflow/.local/lib/python3.8/site-packages/airflow/operators/python.py", line 192, in execute
    return_value = self.execute_callable()
  File "/home/airflow/.local/lib/python3.8/site-packages/airflow/operators/python.py", line 209, in execute_callable
    return self.python_callable(*self.op_args, **self.op_kwargs)
TypeError: limpio_data_frame() missing 1 required positional argument: 'new'
[2023-12-06T00:19:03.616+0000] {taskinstance.py:1400} INFO - Marking task as UP_FOR_RETRY. dag_id=dag_spotify, task_id=limpio_data_frame, execution_date=20231205T230000, start_date=20231206T001903, end_date=20231206T001903
[2023-12-06T00:19:03.622+0000] {standard_task_runner.py:104} ERROR - Failed to execute job 20 for task limpio_data_frame (limpio_data_frame() missing 1 required positional argument: 'new'; 210)
[2023-12-06T00:19:03.632+0000] {local_task_job_runner.py:228} INFO - Task exited with return code 1
[2023-12-06T00:19:03.646+0000] {taskinstance.py:2778} INFO - 0 downstream tasks scheduled from follow-on schedule check
